Workbook

Sheet data
A1: State | B1: price_import [dollar/acre-foot] | C1: price_import [dollar/m3]
A2: ALABAMA | B2: 495.9 | C2: =B2/data_info!B$11 -> 0.40203327
A3: ALASKA | B3: 165 | C3: =B3/data_info!B$11 -> 0.13376788
A4: ARIZONA | B4: 30.18 | C4: =B4/data_info!B$11 -> 0.024467361
A5: ARKANSAS | B5: 49.62 | C5: =B5/data_info!B$11 -> 0.040227649
A6: CALIFORNIA | B6: 67.97 | C6: =B6/data_info!B$11 -> 0.055104258
A7: COLORADO | B7: 14.19 | C7: =B7/data_info!B$11 -> 0.011504037
A8: CONNECTICUT | C8: =B8/data_info!B$11 -> 0
A9: FLORIDA | B9: 124.12 | C9: =B9/data_info!B$11 -> 0.10062587
A10: GEORGIA | B10: 43.59 | C10: =B10/data_info!B$11 -> 0.035339041
A11: HAWAII | B11: 235.42 | C11: =B11/data_info!B$11 -> 0.19085838
A12: IDAHO | B12: 16.78 | C12: =B12/data_info!B$11 -> 0.013603788
A13: ILLINOIS | B13: 42.31 | C13: =B13/data_info!B$11 -> 0.034301326
A14: INDIANA | B14: 150 | C14: =B14/data_info!B$11 -> 0.12160716
A15: IOWA | B15: 62.31 | C15: =B15/data_info!B$11 -> 0.050515614
A16: KANSAS | B16: 41.55 | C16: =B16/data_info!B$11 -> 0.033685183
A17: KENTUCKY | C17: =B17/data_info!B$11 -> 0
A18: LOUISIANA | B18: 254.17 | C18: =B18/data_info!B$11 -> 0.20605928
A19: MAINE | B19: 2486.17 | C19: =B19/data_info!B$11 -> 2.0155738
A20: MARYLAND | B20: 279.4 | C20: =B20/data_info!B$11 -> 0.2265136
A21: MASSACHUSETTS | B21: 432.72 | C21: =B21/data_info!B$11 -> 0.35081234
A22: MINNESOTA | B22: 836.1 | C22: =B22/data_info!B$11 -> 0.67783831
A23: MISSISSIPPI | B23: 135.51 | C23: =B23/data_info!B$11 -> 0.10985991
A24: MISSOURI | B24: 257.02 | C24: =B24/data_info!B$11 -> 0.20836982
A25: MONTANA | B25: 14.81 | C25: =B25/data_info!B$11 -> 0.01200668
A26: NEBRASKA | B26: 32.96 | C26: =B26/data_info!B$11 -> 0.026721147
A27: NEVADA | B27: 11.65 | C27: =B27/data_info!B$11 -> 0.0094448228
A28: NEW HAMPSHIRE | C28: =B28/data_info!B$11 -> 0
A29: NEW JERSEY | B29: 632.43 | C29: =B29/data_info!B$11 -> 0.51272011
A30: NEW MEXICO | B30: 32.4 | C30: =B30/data_info!B$11 -> 0.026267147
A31: NEW YORK | B31: 164.95 | C31: =B31/data_info!B$11 -> 0.13372734
A32: NORTH CAROLINA | B32: 756.67 | C32: =B32/data_info!B$11 -> 0.61344327
A33: NORTH DAKOTA | B33: 50.81 | C33: =B33/data_info!B$11 -> 0.041192399
A34: OHIO | B34: 522.74 | C34: =B34/data_info!B$11 -> 0.42379285
A35: OKLAHOMA | B35: 53.27 | C35: =B35/data_info!B$11 -> 0.043186756
A36: OREGON | B36: 24.22 | C36: =B36/data_info!B$11 -> 0.019635503
A37: PENNSYLVANIA | B37: 270.41 | C37: =B37/data_info!B$11 -> 0.21922528
A38: RHODE ISLAND | B38: 3625 | C38: =B38/data_info!B$11 -> 2.9388397
A39: SOUTH CAROLINA | B39: 171.07 | C39: =B39/data_info!B$11 -> 0.13868891
A40: SOUTH DAKOTA | B40: 25.38 | C40: =B40/data_info!B$11 -> 0.020575932
...

Sheet data_info
A1: info_index | B1: info_value
A2: index_zengarden | B2: price_import
A3: output_fields_zengarden | B3: node, price_import, unit
A4: name_carrier_zengarden | B4: blue_water
A5: name_dataset | B5: WATER, IRRIGATION, SOURCE = OFF FARM - EXPENSE, MEASURED IN $ / ACRE FOOT
A6: source | B6: ‘Water Irrigation Prices’, USDA/NASS QuickStats, 2018, https://quickstats.nass.usda.gov/results/3DF82D93-87C7-3875-9F76-8DF9F0CCD743.
A7: zoterokey | B7: WaterIrrigationPrices2018
A8: unit_input | B8: $ / ACRE FOOT
A9: unit_zengarden | B9: Dollar/watervolumen
A10: conversion_factor_name | B10: acre-foot to m3
A11: conversion_factor_units | B11: 1233.48
A12: column_name_input | B12: price_import [dollar/m3]
A13: year | B13: 2018
